Workbook

Sheet 物资目录
A1: 出入库类型 | B1: 物品名称 | C1: 物品型号 | D1: 物品名称 | E1: 单位 | F1: 物资类型 | G1: 分类 | I1: 出库方式 | J1: 入库方式
A2: 入库 | B2: 簸箕 | C2: 塑料簸箕，45cm | D2: 簸箕 | E2: 个 | F2: 道路保洁 | G2: 工具类 | I2: 员工领用 | J2: 自行采购
A3: 出库 | B3: 簸箕 | C3: 布制兜袋，兜深45cm | D3: 簸箕 | E3: 个 | F3: 道路保洁 | G3: 工具类 | I3: 公司调拨 | J3: 公司发放
B4: 道路保洁扫把 | C4: 中号，1.2m竹叶扫把 | D4: 道路保洁扫把 | E4: 把 | F4: 道路保洁 | G4: 工具类 | I4: 项目调拨 | J4: 项目调拨
B5: 道路保洁扫把 | C5: 大号，1.4m竹叶扫把 | D5: 道路保洁扫把 | E5: 把 | F5: 道路保洁 | G5: 工具类 | I5: 到期报废 | J5: 其他情况
B6: 垃圾夹 | C6: 塑料头钳，80cm | D6: 垃圾夹 | E6: 把 | F6: 道路保洁 | G6: 工具类 | I6: 其他情况
B7: 手套 | C7: 麻布手套 | D7: 手套 | E7: 双 | F7: 道路保洁 | G7: 工具类
B8: 手套 | C8: 黄胶复合防割手套 | D8: 手套 | E8: 双 | F8: 道路保洁 | G8: 工具类
B9: 铁耙 | C9: 九齿钉耙1.2m | D9: 铁耙 | E9: 把 | F9: 道路保洁 | G9: 工具类
B10: 铁耙 | C10: 五齿钉耙1.2m | D10: 铁耙 | E10: 把 | F10: 道路保洁 | G10: 工具类
B11: 铁锹 | C11: 平口铁锹1.2m | D11: 铁锹 | E11: 把 | F11: 道路保洁 | G11: 工具类
B12: 铁锹 | C12: 圆口铁锹1.2m | D12: 铁锹 | E12: 把 | F12: 道路保洁 | G12: 工具类
B13: 垃圾袋 | C13: 100*120cm（240L） | D13: 垃圾袋 | E13: 个 | F13: 道路保洁 | G13: 耗材类
B14: 垃圾袋 | C14: 80*100cm（120L） | D14: 垃圾袋 | E14: 卷 | F14: 道路保洁 | G14: 耗材类
B15: 垃圾夹头 | C15: 绿色12cm胶头 | D15: 垃圾夹头 | E15: 个 | F15: 道路保洁 | G15: 耗材类
B16: 蛇皮袋 | C16: 100*120cm （240L） | D16: 蛇皮袋 | E16: 个 | F16: 道路保洁 | G16: 耗材类
B17: 蛇皮袋 | C17: 80*100cm （120L） | D17: 蛇皮袋 | E17: 个 | F17: 道路保洁 | G17: 耗材类
B18: 自喷漆 | C18: 125ml/瓶，颜色备注 | D18: 自喷漆 | E18: 瓶 | F18: 道路保洁 | G18: 耗材类
... B71: 分离式雨衣 | C71: L | D71: 分离式雨衣 | E71: 套 | F71: 工作服装 | G71: 服装类
B72: 分离式雨衣 | C72: XL | D72: 分离式雨衣 | E72: 套 | F72: 工作服装 | G72: 服装类 | H72: 175
B73: 分离式雨衣 | C73: 2XL | D73: 分离式雨衣 | E73: 套 | F73: 工作服装 | G73: 服装类 | H73: 180
B74: 分离式雨衣 | C74: 3XL | D74: 分离式雨衣 | E74: 套 | F74: 工作服装 | G74: 服装类 | H74: 185
B75: 分离式雨衣 | C75: 4XL | D75: 分离式雨衣 | E75: 套 | F75: 工作服装 | G75: 服装类
B76: 工作帽 | C76: 绿色，均码 | D76: 工作帽 | E76: 个 | F76: 工作服装 | G76: 服装类
B77: 管理层T恤 | C77: M | D77: 管理层T恤 | E77: 套 | F77: 工作服装 | G77: 服装类
B78: 管理层T恤 | C78: L | D78: 管理层T恤 | E78: 套 | F78: 工作服装 | G78: 服装类
B79: 管理层T恤 | C79: XL | D79: 管理层T恤 | E79: 套 | F79: 工作服装 | G79: 服装类
B80: 管理层T恤 | C80: 2XL | D80: 管理层T恤 | E80: 套 | F80: 工作服装 | G80: 服装类
B81: 管理层T恤 | C81: 3XL | D81: 管理层T恤 | E81: 套 | F81: 工作服装 | G81: 服装类
B82: 管理层T恤 | C82: 4XL | D82: 管理层T恤 | E82: 套 | F82: 工作服装 | G82: 服装类
B83: 风油精 | C83: 水仙，5毫克/盒 | D83: 风油精 | E83: 盒 | F83: 礼品类 | G83: 礼品类
B84: 花露水 | C84: 六神，90毫克/瓶 | D84: 花露水 | E84: 瓶 | F84: 礼品类 | G84: 礼品类
B85: 矿泉水 | C85: 印象秀湖，550ml/瓶 | D85: 矿泉水 | E85: 瓶 | F85: 礼品类 | G85: 礼品类
B86: 矿泉水 | C86: 印象秀湖，10.5L/桶 | D86: 矿泉水 | E86: 桶 | F86: 礼品类 | G86: 礼品类
... B157: 捆扎布拖把 | C157: 捆扎布拖把 | D157: 捆扎布拖把 | E157: 个 | F157: 道路保洁 | G157: 工具类

Sheet 表1- 本月物资进出明细账
A1: 塘汇 项目本月物资进出明细单（ 2025 年）
A2: 出入库时间 | B2: 出入库类型 | C2: 物品名称 | D2: 物品型号 | E2: 单位 | F2: 物资类型 | G2: 分类 | H2: 出入库数量 | I2: 领用人（拿走的人） | J2: 实际使用人/使用车 | K2: 具体使用路段/点位 | L2: 入库方式 | M2: 出库方式 | N2: 其他备注
A3: 45962 | B3: 入库 | C3: =VLOOKUP(D3,物资目录!C:G,2,FALSE) -> 榕工机扫车扫刷 | D3: 全钢丝一体式扫刷 | E3: =VLOOKUP(D3,物资目录!C:G,3,FALSE) -> 把 | F3: =VLOOKUP(D3,物资目录!C:G,4,FALSE) -> 机械化保洁 | G3: =VLOOKUP(D3,物资目录!C:G,5,FALSE) -> 耗材类 | H3: 20 | L3: 公司发放
A4: 45962 | B4: 入库 | C4: =VLOOKUP(D4,物资目录!C:G,2,FALSE) -> 道路保洁扫把 | D4: 大号，1.4m竹叶扫把 | E4: =VLOOKUP(D4,物资目录!C:G,3,FALSE) -> 把 | F4: =VLOOKUP(D4,物资目录!C:G,4,FALSE) -> 道路保洁 | G4: =VLOOKUP(D4,物资目录!C:G,5,FALSE) -> 工具类 | H4: 60 | L4: 公司发放
A5: 45962 | B5: 出库 | C5: =VLOOKUP(D5,物资目录!C:G,2,FALSE) -> 簸箕 | D5: 布制兜袋，兜深45cm | E5: =VLOOKUP(D5,物资目录!C:G,3,FALSE) -> 个 | F5: =VLOOKUP(D5,物资目录!C:G,4,FALSE) -> 道路保洁 | G5: =VLOOKUP(D5,物资目录!C:G,5,FALSE) -> 工具类 | H5: 1 | I5: 赵礼菊
A6: 45962 | B6: 出库 | C6: 分离式雨衣 | D6: 2XL | E6: =VLOOKUP(D6,物资目录!C:G,3,FALSE) -> 套 | F6: =VLOOKUP(D6,物资目录!C:G,4,FALSE) -> 工作服装 | G6: =VLOOKUP(D6,物资目录!C:G,5,FALSE) -> 服装类 | H6: 1 | I6: 毕方群
A7: 45962 | B7: 出库 | C7: =VLOOKUP(D7,物资目录!C:G,2,FALSE) -> 手套 | D7: 黄胶复合防割手套 | E7: =VLOOKUP(D7,物资目录!C:G,3,FALSE) -> 双 | F7: =VLOOKUP(D7,物资目录!C:G,4,FALSE) -> 道路保洁 | G7: =VLOOKUP(D7,物资目录!C:G,5,FALSE) -> 工具类 | H7: 12 | I7: 陈洪根
A8: 45962 | B8: 出库 | C8: 保洁冬季工作装 | D8: 2XL | E8: =VLOOKUP(D8,物资目录!C:G,3,FALSE) -> 套 | F8: =VLOOKUP(D8,物资目录!C:G,4,FALSE) -> 工作服装 | G8: =VLOOKUP(D8,物资目录!C:G,5,FALSE) -> 服装类 | H8: 2 | I8: 刘宪蕾
A9: 45962 | B9: 出库 | C9: 分离式雨衣 | D9: 2XL | E9: =VLOOKUP(D9,物资目录!C:G,3,FALSE) -> 套 | F9: =VLOOKUP(D9,物资目录!C:G,4,FALSE) -> 工作服装 | G9: =VLOOKUP(D9,物资目录!C:G,5,FALSE) -> 服装类 | H9: 1 | I9: 刘宪蕾
A10: 45962 | B10: 出库 | C10: =VLOOKUP(D10,物资目录!C:G,2,FALSE) -> 工作帽 | D10: 绿色，均码 | E10: =VLOOKUP(D10,物资目录!C:G,3,FALSE) -> 个 | F10: =VLOOKUP(D10,物资目录!C:G,4,FALSE) -> 工作服装 | G10: =VLOOKUP(D10,物资目录!C:G,5,FALSE) -> 服装类 | H10: 1 | I10: 刘宪蕾
A11: 45962 | B11: 出库 | C11: =VLOOKUP(D11,物资目录!C:G,2,FALSE) -> 安全头盔 | D11: 国标级安全头盔 | E11: =VLOOKUP(D11,物资目录!C:G,3,FALSE) -> 个 | F11: =VLOOKUP(D11,物资目录!C:G,4,FALSE) -> 工作服装 | G11: =VLOOKUP(D11,物资目录!C:G,5,FALSE) -> 服装类 | H11: 1 | I11: 刘宪蕾
A12: 45962 | B12: 出库 | C12: =VLOOKUP(D12,物资目录!C:G,2,FALSE) -> 毛巾 | D12: 30*60cm | E12: =VLOOKUP(D12,物资目录!C:G,3,FALSE) -> 条 | F12: =VLOOKUP(D12,物资目录!C:G,4,FALSE) -> 通用物资 | G12: =VLOOKUP(D12,物资目录!C:G,5,FALSE) -> 工具类 | H12: 6 | I12: 刘宪蕾
A13: 45962 | B13: 出库 | C13: =VLOOKUP(D13,物资目录!C:G,2,FALSE) -> 卷纸 | D13: 180米滚筒式卷纸 | E13: =VLOOKUP(D13,物资目录!C:G,3,FALSE) -> 卷 | F13: =VLOOKUP(D13,物资目录!C:G,4,FALSE) -> 公厕保洁 | G13: =VLOOKUP(D13,物资目录!C:G,5,FALSE) -> 耗材类 | H13: 12 | I13: 于志新 | K13: 茶园公厕
A14: 45962 | B14: 出库 | C14: =VLOOKUP(D14,物资目录!C:G,2,FALSE) -> 手套 | D14: 黄胶复合防割手套 | E14: =VLOOKUP(D14,物资目录!C:G,3,FALSE) -> 双 | F14: =VLOOKUP(D14,物资目录!C:G,4,FALSE) -> 道路保洁 | G14: =VLOOKUP(D14,物资目录!C:G,5,FALSE) -> 工具类 | H14: 6 | I14: 刘宪蕾
A15: 45962 | B15: 出库 | C15: =VLOOKUP(D15,物资目录!C:G,2,FALSE) -> 毛巾 | D15: 30*60cm | E15: =VLOOKUP(D15,物资目录!C:G,3,FALSE) -> 条 | F15: =VLOOKUP(D15,物资目录!C:G,4,FALSE) -> 通用物资 | G15: =VLOOKUP(D15,物资目录!C:G,5,FALSE) -> 工具类 | H15: 1 | I15: 钱凤珍
A16: 45962 | B16: 出库 | C16: =VLOOKUP(D16,物资目录!C:G,2,FALSE) -> 手套 | D16: 黄胶复合防割手套 | E16: =VLOOKUP(D16,物资目录!C:G,3,FALSE) -> 双 | F16: =VLOOKUP(D16,物资目录!C:G,4,FALSE) -> 道路保洁 | G16: =VLOOKUP(D16,物资目录!C:G,5,FALSE) -> 工具类 | H16: 12 | I16: 钱凤珍
A17: 45962 | B17: 出库 | C17: =VLOOKUP(D17,物资目录!C:G,2,FALSE) -> 卷纸 | D17: 180米滚筒式卷纸 | E17: =VLOOKUP(D17,物资目录!C:G,3,FALSE) -> 卷 | F17: =VLOOKUP(D17,物资目录!C:G,4,FALSE) -> 公厕保洁 | G17: =VLOOKUP(D17,物资目录!C:G,5,FALSE) -> 耗材类 | H17: 1 | I17: 于志新 | K17: 永政公厕
A18: 45962 | B18: 出库 | C18: =VLOOKUP(D18,物资目录!C:G,2,FALSE) -> 垃圾袋 | D18: 45*60cm | E18: =VLOOKUP(D18,物资目录!C:G,3,FALSE) -> 卷 | F18: =VLOOKUP(D18,物资目录!C:G,4,FALSE) -> 公厕保洁 | G18: =VLOOKUP(D18,物资目录!C:G,5,FALSE) -> 耗材类 | H18: 3 | I18: 于志新 | K18: 永政公厕
A19: 45962 | B19: 出库 | C19: =VLOOKUP(D19,物资目录!C:G,2,FALSE) -> 檀香 | D19: 李字牌，10盘一盒 | E19: =VLOOKUP(D19,物资目录!C:G,3,FALSE) -> 盒 | F19: =VLOOKUP(D19,物资目录!C:G,4,FALSE) -> 公厕保洁 | G19: =VLOOKUP(D19,物资目录!C:G,5,FALSE) -> 耗材类 | H19: 3 | I19: 于志新 | K19: 永政公厕
A20: 45962 | B20: 出库 | C20: =VLOOKUP(D20,物资目录!C:G,2,FALSE) -> 芳香球 | D20: 5个一包 | E20: =VLOOKUP(D20,物资目录!C:G,3,FALSE) -> 包 | F20: =VLOOKUP(D20,物资目录!C:G,4,FALSE) -> 公厕保洁 | G20: =VLOOKUP(D20,物资目录!C:G,5,FALSE) -> 耗材类 | H20: 1 | I20: 于志新 | K20: 永政公厕
A21: 45963 | B21: 出库 | C21: =VLOOKUP(D21,物资目录!C:G,2,FALSE) -> 卷纸 | D21: 180米滚筒式卷纸 | E21: =VLOOKUP(D21,物资目录!C:G,3,FALSE) -> 卷 | F21: =VLOOKUP(D21,物资目录!C:G,4,FALSE) -> 公厕保洁 | G21: =VLOOKUP(D21,物资目录!C:G,5,FALSE) -> 耗材类 | H21: 12 | I21: 于志新 | K21: 长纤塘公厕
A22: 45963 | B22: 出库 | C22: =VLOOKUP(D22,物资目录!C:G,2,FALSE) -> 洗手液 | D22: 新涤德，500g/瓶 | E22: =VLOOKUP(D22,物资目录!C:G,3,FALSE) -> 瓶 | F22: =VLOOKUP(D22,物资目录!C:G,4,FALSE) -> 公厕保洁 | G22: =VLOOKUP(D22,物资目录!C:G,5,FALSE) -> 耗材类 | H22: 4 | I22: 于志新 | K22: 长纤塘公厕
A23: 45963 | B23: 出库 | C23: =VLOOKUP(D23,物资目录!C:G,2,FALSE) -> 84消毒液 | D23: 518ML/瓶 | E23: =VLOOKUP(D23,物资目录!C:G,3,FALSE) -> 瓶 | F23: =VLOOKUP(D23,物资目录!C:G,4,FALSE) -> 公厕保洁 | G23: =VLOOKUP(D23,物资目录!C:G,5,FALSE) -> 耗材类 | H23: 3 | I23: 于志新 | K23: 长纤塘公厕
A24: 45963 | B24: 出库 | C24: =VLOOKUP(D24,物资目录!C:G,2,FALSE) -> 垃圾袋 | D24: 45*60cm | E24: =VLOOKUP(D24,物资目录!C:G,3,FALSE) -> 卷 | F24: =VLOOKUP(D24,物资目录!C:G,4,FALSE) -> 公厕保洁 | G24: =VLOOKUP(D24,物资目录!C:G,5,FALSE) -> 耗材类 | H24: 5 | I24: 于志新 | K24: 长纤塘公厕
A25: 45963 | B25: 出库 | C25: =VLOOKUP(D25,物资目录!C:G,2,FALSE) -> 垃圾袋 | D25: 60*80cm | E25: =VLOOKUP(D25,物资目录!C:G,3,FALSE) -> 个 | F25: =VLOOKUP(D25,物资目录!C:G,4,FALSE) -> 公厕保洁 | G25: =VLOOKUP(D25,物资目录!C:G,5,FALSE) -> 耗材类 | H25: 3 | I25: 于志新 | K25: 长纤塘公厕
A26: 45963 | B26: 出库 | C26: =VLOOKUP(D26,物资目录!C:G,2,FALSE) -> 垃圾袋 | D26: 80*100cm（120L） | E26: =VLOOKUP(D26,物资目录!C:G,3,FALSE) -> 卷 | F26: =VLOOKUP(D26,物资目录!C:G,4,FALSE) -> 道路保洁 | G26: =VLOOKUP(D26,物资目录!C:G,5,FALSE) -> 耗材类 | H26: 1 | I26: 于志新 | K26: 长纤塘公厕
A27: 45963 | B27: 出库 | C27: =VLOOKUP(D27,物资目录!C:G,2,FALSE) -> 檀香 | D27: 李字牌，10盘一盒 | E27: =VLOOKUP(D27,物资目录!C:G,3,FALSE) -> 盒 | F27: =VLOOKUP(D27,物资目录!C:G,4,FALSE) -> 公厕保洁 | G27: =VLOOKUP(D27,物资目录!C:G,5,FALSE) -> 耗材类 | H27: 5 | I27: 于志新 | K27: 长纤塘公厕
A28: 45964 | B28: 出库 | C28: =VLOOKUP(D28,物资目录!C:G,2,FALSE) -> 洗洁精 | D28: 白猫洗洁精，2kg/瓶 | E28: =VLOOKUP(D28,物资目录!C:G,3,FALSE) -> 瓶 | F28: =VLOOKUP(D28,物资目录!C:G,4,FALSE) -> 公厕保洁 | G28: =VLOOKUP(D28,物资目录!C:G,5,FALSE) -> 耗材类 | H28: 2 | I28: 于志新
A29: 45964 | B29: 出库 | C29: =VLOOKUP(D29,物资目录!C:G,2,FALSE) -> 垃圾袋 | D29: 45*60cm | E29: =VLOOKUP(D29,物资目录!C:G,3,FALSE) -> 卷 | F29: =VLOOKUP(D29,物资目录!C:G,4,FALSE) -> 公厕保洁 | G29: =VLOOKUP(D29,物资目录!C:G,5,FALSE) -> 耗材类 | H29: 10 | I29: 于志新
A30: 45964 | B30: 出库 | C30: =VLOOKUP(D30,物资目录!C:G,2,FALSE) -> 84消毒液 | D30: 518ML/瓶 | E30: =VLOOKUP(D30,物资目录!C:G,3,FALSE) -> 瓶 | F30: =VLOOKUP(D30,物资目录!C:G,4,FALSE) -> 公厕保洁 | G30: =VLOOKUP(D30,物资目录!C:G,5,FALSE) -> 耗材类 | H30: 3 | I30: 于志新
A31: 45964 | B31: 出库 | C31: =VLOOKUP(D31,物资目录!C:G,2,FALSE) -> 洗手液 | D31: 新涤德，500g/瓶 | E31: =VLOOKUP(D31,物资目录!C:G,3,FALSE) -> 瓶 | F31: =VLOOKUP(D31,物资目录!C:G,4,FALSE) -> 公厕保洁 | G31: =VLOOKUP(D31,物资目录!C:G,5,FALSE) -> 耗材类 | H31: 1 | I31: 于志新
A32: 45964 | B32: 出库 | C32: =VLOOKUP(D32,物资目录!C:G,2,FALSE) -> 檀香 | D32: 李字牌，10盘一盒 | E32: =VLOOKUP(D32,物资目录!C:G,3,FALSE) -> 盒 | F32: =VLOOKUP(D32,物资目录!C:G,4,FALSE) -> 公厕保洁 | G32: =VLOOKUP(D32,物资目录!C:G,5,FALSE) -> 耗材类 | H32: 6 | I32: 于志新
A33: 45964 | B33: 出库 | C33: =VLOOKUP(D33,物资目录!C:G,2,FALSE) -> 垃圾袋 | D33: 60*80cm | E33: =VLOOKUP(D33,物资目录!C:G,3,FALSE) -> 个 | F33: =VLOOKUP(D33,物资目录!C:G,4,FALSE) -> 公厕保洁 | G33: =VLOOKUP(D33,物资目录!C:G,5,FALSE) -> 耗材类 | H33: 5 | I33: 于志新
A34: 45964 | B34: 出库 | C34: =VLOOKUP(D34,物资目录!C:G,2,FALSE) -> 芳香球 | D34: 5个一包 | E34: =VLOOKUP(D34,物资目录!C:G,3,FALSE) -> 包 | F34: =VLOOKUP(D34,物资目录!C:G,4,FALSE) -> 公厕保洁 | G34: =VLOOKUP(D34,物资目录!C:G,5,FALSE) -> 耗材类 | H34: 2 | I34: 于志新
A35: 45964 | B35: 出库 | C35: =VLOOKUP(D35,物资目录!C:G,2,FALSE) -> 洁厕液 | D35: 威猛500ML/瓶 | E35: =VLOOKUP(D35,物资目录!C:G,3,FALSE) -> 瓶 | F35: =VLOOKUP(D35,物资目录!C:G,4,FALSE) -> 公厕保洁 | G35: =VLOOKUP(D35,物资目录!C:G,5,FALSE) -> 耗材类 | H35: 2 | I35: 于志新
A36: 45964 | B36: 出库 | C36: =VLOOKUP(D36,物资目录!C:G,2,FALSE) -> 毛巾 | D36: 30*60cm | E36: =VLOOKUP(D36,物资目录!C:G,3,FALSE) -> 条 | F36: =VLOOKUP(D36,物资目录!C:G,4,FALSE) -> 通用物资 | G36: =VLOOKUP(D36,物资目录!C:G,5,FALSE) -> 工具类 | H36: 2 | I36: 李运山
A37: 45965 | B37: 出库 | C37: =VLOOKUP(D37,物资目录!C:G,2,FALSE) -> 垃圾夹 | D37: 塑料头钳，80cm | E37: =VLOOKUP(D37,物资目录!C:G,3,FALSE) -> 把 | F37: =VLOOKUP(D37,物资目录!C:G,4,FALSE) -> 道路保洁 | G37: =VLOOKUP(D37,物资目录!C:G,5,FALSE) -> 工具类 | H37: 1 | I37: 李运山
A38: 45966 | B38: 出库 | C38: =VLOOKUP(D38,物资目录!C:G,2,FALSE) -> 卷纸 | D38: 180米滚筒式卷纸 | E38: =VLOOKUP(D38,物资目录!C:G,3,FALSE) -> 卷 | F38: =VLOOKUP(D38,物资目录!C:G,4,FALSE) -> 公厕保洁 | G38: =VLOOKUP(D38,物资目录!C:G,5,FALSE) -> 耗材类 | H38: 2 | K38: 办公室
A39: 45966 | B39: 出库 | C39: =VLOOKUP(D39,物资目录!C:G,2,FALSE) -> 毛巾 | D39: 30*60cm | E39: =VLOOKUP(D39,物资目录!C:G,3,FALSE) -> 条 | F39: =VLOOKUP(D39,物资目录!C:G,4,FALSE) -> 通用物资 | G39: =VLOOKUP(D39,物资目录!C:G,5,FALSE) -> 工具类 | H39: 1 | I39: 吴福荣
A40: 45966 | B40: 出库 | C40: =VLOOKUP(D40,物资目录!C:G,2,FALSE) -> 手套 | D40: 黄胶复合防割手套 | E40: =VLOOKUP(D40,物资目录!C:G,3,FALSE) -> 双 | F40: =VLOOKUP(D40,物资目录!C:G,4,FALSE) -> 道路保洁 | G40: =VLOOKUP(D40,物资目录!C:G,5,FALSE) -> 工具类 | H40: 12 | I40: 赖长贵
...

Sheet 表2- 本月物资进出汇总表（自动汇总）
A1: 塘汇 项目仓储明细单（ 2025 年 11 月） | I1: （黄色列会根据表1自动汇总，只要月底盘库，核对结余数量，内嵌公式）
A2: 序号 | B2: 物品名称 | C2: 物品型号 | D2: 单位 | E2: 物资类型 | F2: 分类 | G2: 上月末结余数量（复制数据） | H2: 本月入库数量 | I2: 本月发放数量 | J2: 本月末结余数量（表上数据要与仓库实数核对） | K2: 备注
A3: =ROW()-2 -> 1 | B3: 簸箕 | C3: 塑料簸箕，45cm | D3: 个 | E3: 道路保洁 | F3: 工具类 | G3: 0 | H3: =SUMIFS('表1- 本月物资进出明细账'!H:H,'表1- 本月物资进出明细账'!B:B,"入库",'表1- 本月物资进出明细账'!C:C,B:B,'表1- 本月物资进出明细账'!D:D,C:C) -> 0 | I3: =SUMIFS('表1- 本月物资进出明细账'!H:H,'表1- 本月物资进出明细账'!B:B,"出库",'表1- 本月物资进出明细账'!C:C,B:B,'表1- 本月物资进出明细账'!D:D,C:C) -> 0 | J3: =G3+H3-I3 -> 0
A4: =ROW()-2 -> 2 | B4: 簸箕 | C4: 布制兜袋，兜深45cm | D4: 个 | E4: 道路保洁 | F4: 工具类 | G4: 9 | H4: =SUMIFS('表1- 本月物资进出明细账'!H:H,'表1- 本月物资进出明细账'!B:B,"入库",'表1- 本月物资进出明细账'!C:C,B:B,'表1- 本月物资进出明细账'!D:D,C:C) -> 0 | I4: =SUMIFS('表1- 本月物资进出明细账'!H:H,'表1- 本月物资进出明细账'!B:B,"出库",'表1- 本月物资进出明细账'!C:C,B:B,'表1- 本月物资进出明细账'!D:D,C:C) -> 1 | J4: =G4+H4-I4 -> 8
A5: =ROW()-2 -> 3 | B5: 道路保洁扫把 | C5: 中号，1.2m竹叶扫把 | D5: 把 | E5: 道路保洁 | F5: 工具类 | G5: 216 | H5: =SUMIFS('表1- 本月物资进出明细账'!H:H,'表1- 本月物资进出明细账'!B:B,"入库",'表1- 本月物资进出明细账'!C:C,B:B,'表1- 本月物资进出明细账'!D:D,C:C) -> 0 | I5: =SUMIFS('表1- 本月物资进出明细账'!H:H,'表1- 本月物资进出明细账'!B:B,"出库",'表1- 本月物资进出明细账'!C:C,B:B,'表1- 本月物资进出明细账'!D:D,C:C) -> 74 | J5: =G5+H5-I5 -> 142
A6: =ROW()-2 -> 4 | B6: 道路保洁扫把 | C6: 大号，1.4m竹叶扫把 | D6: 把 | E6: 道路保洁 | F6: 工具类 | G6: 0 | H6: =SUMIFS('表1- 本月物资进出明细账'!H:H,'表1- 本月物资进出明细账'!B:B,"入库",'表1- 本月物资进出明细账'!C:C,B:B,'表1- 本月物资进出明细账'!D:D,C:C) -> 60 | I6: =SUMIFS('表1- 本月物资进出明细账'!H:H,'表1- 本月物资进出明细账'!B:B,"出库",'表1- 本月物资进出明细账'!C:C,B:B,'表1- 本月物资进出明细账'!D:D,C:C) -> 0 | J6: =G6+H6-I6 -> 60
A7: =ROW()-2 -> 5 | B7: 垃圾夹 | C7: 塑料头钳，80cm | D7: 把 | E7: 道路保洁 | F7: 工具类 | G7: 56 | H7: =SUMIFS('表1- 本月物资进出明细账'!H:H,'表1- 本月物资进出明细账'!B:B,"入库",'表1- 本月物资进出明细账'!C:C,B:B,'表1- 本月物资进出明细账'!D:D,C:C) -> 0 | I7: =SUMIFS('表1- 本月物资进出明细账'!H:H,'表1- 本月物资进出明细账'!B:B,"出库",'表1- 本月物资进出明细账'!C:C,B:B,'表1- 本月物资进出明细账'!D:D,C:C) -> 12 | J7: =G7+H7-I7 -> 44
A8: =ROW()-2 -> 6 | B8: 手套 | C8: 麻布手套 | D8: 双 | E8: 道路保洁 | F8: 工具类 | G8: 0 | H8: =SUMIFS('表1- 本月物资进出明细账'!H:H,'表1- 本月物资进出明细账'!B:B,"入库",'表1- 本月物资进出明细账'!C:C,B:B,'表1- 本月物资进出明细账'!D:D,C:C) -> 0 | I8: =SUMIFS('表1- 本月物资进出明细账'!H:H,'表1- 本月物资进出明细账'!B:B,"出库",'表1- 本月物资进出明细账'!C:C,B:B,'表1- 本月物资进出明细账'!D:D,C:C) -> 0 | J8: =G8+H8-I8 -> 0
A9: =ROW()-2 -> 7 | B9: 手套 | C9: 黄胶复合防割手套 | D9: 双 | E9: 道路保洁 | F9: 工具类 | G9: 315 | H9: =SUMIFS('表1- 本月物资进出明细账'!H:H,'表1- 本月物资进出明细账'!B:B,"入库",'表1- 本月物资进出明细账'!C:C,B:B,'表1- 本月物资进出明细账'!D:D,C:C) -> 0 | I9: =SUMIFS('表1- 本月物资进出明细账'!H:H,'表1- 本月物资进出明细账'!B:B,"出库",'表1- 本月物资进出明细账'!C:C,B:B,'表1- 本月物资进出明细账'!D:D,C:C) -> 114 | J9: =G9+H9-I9 -> 201
A10: =ROW()-2 -> 8 | B10: 铁耙 | C10: 九齿钉耙1.2m | D10: 把 | E10: 道路保洁 | F10: 工具类 | G10: 21 | H10: =SUMIFS('表1- 本月物资进出明细账'!H:H,'表1- 本月物资进出明细账'!B:B,"入库",'表1- 本月物资进出明细账'!C:C,B:B,'表1- 本月物资进出明细账'!D:D,C:C) -> 0 | I10: =SUMIFS('表1- 本月物资进出明细账'!H:H,'表1- 本月物资进出明细账'!B:B,"出库",'表1- 本月物资进出明细账'!C:C,B:B,'表1- 本月物资进出明细账'!D:D,C:C) -> 0 | J10: =G10+H10-I10 -> 21
A11: =ROW()-2 -> 9 | B11: 铁耙 | C11: 五齿钉耙1.2m | D11: 把 | E11: 道路保洁 | F11: 工具类 | G11: 0 | H11: =SUMIFS('表1- 本月物资进出明细账'!H:H,'表1- 本月物资进出明细账'!B:B,"入库",'表1- 本月物资进出明细账'!C:C,B:B,'表1- 本月物资进出明细账'!D:D,C:C) -> 0 | I11: =SUMIFS('表1- 本月物资进出明细账'!H:H,'表1- 本月物资进出明细账'!B:B,"出库",'表1- 本月物资进出明细账'!C:C,B:B,'表1- 本月物资进出明细账'!D:D,C:C) -> 0 | J11: =G11+H11-I11 -> 0
A12: =ROW()-2 -> 10 | B12: 铁锹 | C12: 平口铁锹1.2m | D12: 把 | E12: 道路保洁 | F12: 工具类 | G12: 4 | H12: =SUMIFS('表1- 本月物资进出明细账'!H:H,'表1- 本月物资进出明细账'!B:B,"入库",'表1- 本月物资进出明细账'!C:C,B:B,'表1- 本月物资进出明细账'!D:D,C:C) -> 0 | I12: =SUMIFS('表1- 本月物资进出明细账'!H:H,'表1- 本月物资进出明细账'!B:B,"出库",'表1- 本月物资进出明细账'!C:C,B:B,'表1- 本月物资进出明细账'!D:D,C:C) -> 1 | J12: =G12+H12-I12 -> 3
A13: =ROW()-2 -> 11 | B13: 铁锹 | C13: 圆口铁锹1.2m | D13: 把 | E13: 道路保洁 | F13: 工具类 | G13: 0 | H13: =SUMIFS('表1- 本月物资进出明细账'!H:H,'表1- 本月物资进出明细账'!B:B,"入库",'表1- 本月物资进出明细账'!C:C,B:B,'表1- 本月物资进出明细账'!D:D,C:C) -> 0 | I13: =SUMIFS('表1- 本月物资进出明细账'!H:H,'表1- 本月物资进出明细账'!B:B,"出库",'表1- 本月物资进出明细账'!C:C,B:B,'表1- 本月物资进出明细账'!D:D,C:C) -> 0 | J13: =G13+H13-I13 -> 0
A14: =ROW()-2 -> 12 | B14: 垃圾袋 | C14: 100*120cm（240L） | D14: 个 | E14: 道路保洁 | F14: 耗材类 | G14: 5.5 | H14: =SUMIFS('表1- 本月物资进出明细账'!H:H,'表1- 本月物资进出明细账'!B:B,"入库",'表1- 本月物资进出明细账'!C:C,B:B,'表1- 本月物资进出明细账'!D:D,C:C) -> 0 | I14: =SUMIFS('表1- 本月物资进出明细账'!H:H,'表1- 本月物资进出明细账'!B:B,"出库",'表1- 本月物资进出明细账'!C:C,B:B,'表1- 本月物资进出明细账'!D:D,C:C) -> 1 | J14: =G14+H14-I14 -> 4.5
... A100: =ROW()-2 -> 98 | B100: 镰刀 | C100: 弯月式短割草刀 | D100: 把 | E100: 道路保洁 | F100: 工具类 | G100: 5 | H100: =SUMIFS('表1- 本月物资进出明细账'!H:H,'表1- 本月物资进出明细账'!B:B,"入库",'表1- 本月物资进出明细账'!C:C,B:B,'表1- 本月物资进出明细账'!D:D,C:C) -> 0 | I100: =SUMIFS('表1- 本月物资进出明细账'!H:H,'表1- 本月物资进出明细账'!B:B,"出库",'表1- 本月物资进出明细账'!C:C,B:B,'表1- 本月物资进出明细账'!D:D,C:C) -> 0 | J100: =G100+H100-I100 -> 5
A101: =ROW()-2 -> 99 | B101: 扫把 | C101: 塑料扫把簸箕一体式 | D101: 套 | E101: 公厕保洁 | F101: 工具类 | G101: 11 | H101: =SUMIFS('表1- 本月物资进出明细账'!H:H,'表1- 本月物资进出明细账'!B:B,"入库",'表1- 本月物资进出明细账'!C:C,B:B,'表1- 本月物资进出明细账'!D:D,C:C) -> 0 | I101: =SUMIFS('表1- 本月物资进出明细账'!H:H,'表1- 本月物资进出明细账'!B:B,"出库",'表1- 本月物资进出明细账'!C:C,B:B,'表1- 本月物资进出明细账'!D:D,C:C) -> 1 | J101: =G101+H101-I101 -> 10 | K101: 其中4套无簸箕
A102: =ROW()-2 -> 100 | B102: 十字镐 | C102: 十字锥镐1.2m | D102: 把 | E102: 道路保洁 | F102: 工具类 | G102: 2 | H102: =SUMIFS('表1- 本月物资进出明细账'!H:H,'表1- 本月物资进出明细账'!B:B,"入库",'表1- 本月物资进出明细账'!C:C,B:B,'表1- 本月物资进出明细账'!D:D,C:C) -> 0 | I102: =SUMIFS('表1- 本月物资进出明细账'!H:H,'表1- 本月物资进出明细账'!B:B,"出库",'表1- 本月物资进出明细账'!C:C,B:B,'表1- 本月物资进出明细账'!D:D,C:C) -> 0 | J102: =G102+H102-I102 -> 2
A103: =ROW()-2 -> 101 | B103: 黄油 | C103: 车用 | D103: 瓶 | E103: 机械化保洁 | F103: 耗材类 | G103: 0 | H103: =SUMIFS('表1- 本月物资进出明细账'!H:H,'表1- 本月物资进出明细账'!B:B,"入库",'表1- 本月物资进出明细账'!C:C,B:B,'表1- 本月物资进出明细账'!D:D,C:C) -> 0 | I103: =SUMIFS('表1- 本月物资进出明细账'!H:H,'表1- 本月物资进出明细账'!B:B,"出库",'表1- 本月物资进出明细账'!C:C,B:B,'表1- 本月物资进出明细账'!D:D,C:C) -> 0 | J103: =G103+H103-I103 -> 0
A104: =ROW()-2 -> 102 | B104: 机油 | C104: 车用 | D104: 瓶 | E104: 机械化保洁 | F104: 耗材类 | G104: 0 | H104: =SUMIFS('表1- 本月物资进出明细账'!H:H,'表1- 本月物资进出明细账'!B:B,"入库",'表1- 本月物资进出明细账'!C:C,B:B,'表1- 本月物资进出明细账'!D:D,C:C) -> 0 | I104: =SUMIFS('表1- 本月物资进出明细账'!H:H,'表1- 本月物资进出明细账'!B:B,"出库",'表1- 本月物资进出明细账'!C:C,B:B,'表1- 本月物资进出明细账'!D:D,C:C) -> 0 | J104: =G104+H104-I104 -> 0
A105: =ROW()-2 -> 103 | B105: 液压油 | C105: 车用 | D105: 瓶 | E105: 机械化保洁 | F105: 耗材类 | G105: 0 | H105: =SUMIFS('表1- 本月物资进出明细账'!H:H,'表1- 本月物资进出明细账'!B:B,"入库",'表1- 本月物资进出明细账'!C:C,B:B,'表1- 本月物资进出明细账'!D:D,C:C) -> 0 | I105: =SUMIFS('表1- 本月物资进出明细账'!H:H,'表1- 本月物资进出明细账'!B:B,"出库",'表1- 本月物资进出明细账'!C:C,B:B,'表1- 本月物资进出明细账'!D:D,C:C) -> 0 | J105: =G105+H105-I105 -> 0
A106: =ROW()-2 -> 104 | B106: 百洁布 | C106: 小方吸水百洁布 | D106: 块 | E106: 公厕保洁 | F106: 工具类 | G106: 25 | H106: =SUMIFS('表1- 本月物资进出明细账'!H:H,'表1- 本月物资进出明细账'!B:B,"入库",'表1- 本月物资进出明细账'!C:C,B:B,'表1- 本月物资进出明细账'!D:D,C:C) -> 0 | I106: =SUMIFS('表1- 本月物资进出明细账'!H:H,'表1- 本月物资进出明细账'!B:B,"出库",'表1- 本月物资进出明细账'!C:C,B:B,'表1- 本月物资进出明细账'!D:D,C:C) -> 0 | J106: =G106+H106-I106 -> 25
A107: =ROW()-2 -> 105 | B107: 反光背心 | C107: 均码反光背心 | D107: 套 | E107: 工作服装 | F107: 服装类 | G107: 0 | H107: =SUMIFS('表1- 本月物资进出明细账'!H:H,'表1- 本月物资进出明细账'!B:B,"入库",'表1- 本月物资进出明细账'!C:C,B:B,'表1- 本月物资进出明细账'!D:D,C:C) -> 0 | I107: =SUMIFS('表1- 本月物资进出明细账'!H:H,'表1- 本月物资进出明细账'!B:B,"出库",'表1- 本月物资进出明细账'!C:C,B:B,'表1- 本月物资进出明细账'!D:D,C:C) -> 0 | J107: =G107+H107-I107 -> 0
A108: =ROW()-2 -> 106 | B108: 肩灯 | C108: 多功能LED肩灯 | D108: 个 | E108: 道路保洁 | F108: 工具类 | G108: 0 | H108: =SUMIFS('表1- 本月物资进出明细账'!H:H,'表1- 本月物资进出明细账'!B:B,"入库",'表1- 本月物资进出明细账'!C:C,B:B,'表1- 本月物资进出明细账'!D:D,C:C) -> 0 | I108: =SUMIFS('表1- 本月物资进出明细账'!H:H,'表1- 本月物资进出明细账'!B:B,"出库",'表1- 本月物资进出明细账'!C:C,B:B,'表1- 本月物资进出明细账'!D:D,C:C) -> 0 | J108: =G108+H108-I108 -> 0
A109: =ROW()-2 -> 107 | B109: 钢丝球 | C109: 细丝钢丝球刷 | D109: 个 | E109: 通用物资 | F109: 工具类 | G109: 0 | H109: =SUMIFS('表1- 本月物资进出明细账'!H:H,'表1- 本月物资进出明细账'!B:B,"入库",'表1- 本月物资进出明细账'!C:C,B:B,'表1- 本月物资进出明细账'!D:D,C:C) -> 0 | I109: =SUMIFS('表1- 本月物资进出明细账'!H:H,'表1- 本月物资进出明细账'!B:B,"出库",'表1- 本月物资进出明细账'!C:C,B:B,'表1- 本月物资进出明细账'!D:D,C:C) -> 0 | J109: =G109+H109-I109 -> 0
A110: =ROW()-2 -> 108 | B110: 救生衣 | C110: 马甲式黄色反光救生衣 | D110: 件 | E110: 工作服装 | F110: 服装类 | G110: 0 | H110: =SUMIFS('表1- 本月物资进出明细账'!H:H,'表1- 本月物资进出明细账'!B:B,"入库",'表1- 本月物资进出明细账'!C:C,B:B,'表1- 本月物资进出明细账'!D:D,C:C) -> 0 | I110: =SUMIFS('表1- 本月物资进出明细账'!H:H,'表1- 本月物资进出明细账'!B:B,"出库",'表1- 本月物资进出明细账'!C:C,B:B,'表1- 本月物资进出明细账'!D:D,C:C) -> 0 | J110: =G110+H110-I110 -> 0
A111: =ROW()-2 -> 109 | B111: 安全头盔 | C111: 国标级安全头盔 | D111: 个 | E111: 工作服装 | F111: 服装类 | G111: 85 | H111: =SUMIFS('表1- 本月物资进出明细账'!H:H,'表1- 本月物资进出明细账'!B:B,"入库",'表1- 本月物资进出明细账'!C:C,B:B,'表1- 本月物资进出明细账'!D:D,C:C) -> 0 | I111: =SUMIFS('表1- 本月物资进出明细账'!H:H,'表1- 本月物资进出明细账'!B:B,"出库",'表1- 本月物资进出明细账'!C:C,B:B,'表1- 本月物资进出明细账'!D:D,C:C) -> 2 | J111: =G111+H111-I111 -> 83
A112: =ROW()-2 -> 110 | B112: 马桶抽 | C112: 皮质马桶抽 | D112: 把 | E112: 公厕保洁 | F112: 工具类 | G112: 8 | H112: =SUMIFS('表1- 本月物资进出明细账'!H:H,'表1- 本月物资进出明细账'!B:B,"入库",'表1- 本月物资进出明细账'!C:C,B:B,'表1- 本月物资进出明细账'!D:D,C:C) -> 0 | I112: =SUMIFS('表1- 本月物资进出明细账'!H:H,'表1- 本月物资进出明细账'!B:B,"出库",'表1- 本月物资进出明细账'!C:C,B:B,'表1- 本月物资进出明细账'!D:D,C:C) -> 0 | J112: =G112+H112-I112 -> 8
A113: =ROW()-2 -> 111 | B113: 马桶刷 | C113: 塑料毛质马桶刷 | D113: 把 | E113: 公厕保洁 | F113: 工具类 | G113: 0 | H113: =SUMIFS('表1- 本月物资进出明细账'!H:H,'表1- 本月物资进出明细账'!B:B,"入库",'表1- 本月物资进出明细账'!C:C,B:B,'表1- 本月物资进出明细账'!D:D,C:C) -> 0 | I113: =SUMIFS('表1- 本月物资进出明细账'!H:H,'表1- 本月物资进出明细账'!B:B,"出库",'表1- 本月物资进出明细账'!C:C,B:B,'表1- 本月物资进出明细账'!D:D,C:C) -> 0 | J113: =G113+H113-I113 -> 0
... A158: =ROW()-2 -> 156 | B158: 捆扎布拖把 | C158: 捆扎布拖把 | D158: 个 | E158: 道路保洁 | F158: 工具类 | G158: 1 | H158: =SUMIFS('表1- 本月物资进出明细账'!H:H,'表1- 本月物资进出明细账'!B:B,"入库",'表1- 本月物资进出明细账'!C:C,B:B,'表1- 本月物资进出明细账'!D:D,C:C) -> 0 | I158: =SUMIFS('表1- 本月物资进出明细账'!H:H,'表1- 本月物资进出明细账'!B:B,"出库",'表1- 本月物资进出明细账'!C:C,B:B,'表1- 本月物资进出明细账'!D:D,C:C) -> 0 | J158: =G158+H158-I158 -> 1
G159: =SUM(G3:G158) -> 6985.1 | H159: =SUM(H3:H158) -> 110 | I159: =SUM(I3:I158) -> 1214 | J159: =SUM(J3:J158) -> 5881.1

Sheet 表3- 月数据自动汇总
A1: 月数据自动汇总（操作）：
A5: 一、按物资进出账汇总数据 | H5: 二、按各路段物资使用汇总数据 | N5: 三、按不同的领用人管理物资使用汇总数据
A6: 求和项:出入库数量 | B6: 出入库类型 | H6: 出入库类型 | I6: 物品名称 | J6: 求和项:出入库数量 | N6: 出入库类型 | O6: 物品名称 | P6: 求和项:出入库数量
A7: 物品名称 | B7: 入库 | C7: (空白) | D7: 总计 | H7: 入库 | J7: 2038 | N7: 入库 | P7: 2038
A8: 除油片 | B8: 1 | D8: 1 | I8: 除油片 | J8: 1 | O8: 除油片 | P8: 1
A9: (空白) | I9: 大铲刀 | J9: 1 | O9: 大铲刀 | P9: 1
A10: 铁耙 | B10: 18 | D10: 18 | I10: 手拉锯子 | J10: 2 | O10: 手拉锯子 | P10: 2
A11: 铲刀 | B11: 28 | D11: 28 | I11: 锄头 | J11: 2 | O11: 锄头 | P11: 2
A12: 垃圾夹 | B12: 62 | D12: 62 | I12: 捆扎布拖把 | J12: 3 | O12: 捆扎布拖把 | P12: 3
A13: 水桶 | B13: 9 | D13: 9 | I13: 洗衣粉 | J13: 4 | O13: 洗衣粉 | P13: 4
A14: 檀香 | B14: 30 | D14: 30 | I14: 马桶抽 | J14: 6 | O14: 马桶抽 | P14: 6
A15: 马桶抽 | B15: 6 | D15: 6 | I15: 除尘担 | J15: 6 | O15: 除尘担 | P15: 6
A16: 铁锹 | B16: 11 | D16: 11 | I16: 拖把 | J16: 7 | O16: 拖把 | P16: 7
A17: 洗洁精 | B17: 24 | D17: 24 | I17: 镰刀 | J17: 7 | O17: 镰刀 | P17: 7
A18: 垃圾袋 | B18: 485 | D18: 485 | I18: 自喷漆 | J18: 8 | O18: 自喷漆 | P18: 8
A19: 道路保洁扫把 | B19: 95 | D19: 95 | I19: 扫把 | J19: 8 | O19: 扫把 | P19: 8
A20: 手套 | B20: 687 | D20: 687 | I20: 水桶 | J20: 9 | O20: 水桶 | P20: 9
A21: 自喷漆 | B21: 8 | D21: 8 | I21: 铁锹 | J21: 11 | O21: 铁锹 | P21: 11
... A36: 小凳子 | B36: 37 | D36: 37 | I36: 手套 | J36: 687 | O36: 手套 | P36: 687
A37: 捆扎布拖把 | B37: 3 | D37: 3 | H37: (空白) | N37: (空白)
A38: 总计 | B38: 2038 | D38: 2038 | I38: (空白) | O38: (空白)
H39: 总计 | J39: 2038 | N39: 总计 | P39: 2038

Sheet 表4- 展示给李总
A3: 物资类型 | B3: 计数项:本月发放数量
A4: 道路保洁 | B4: 17
A5: 工作服装 | B5: 26
A6: 公厕保洁 | B6: 16
A7: 河道保洁 | B7: 1
A8: 机械化保洁 | B8: 5
A9: 礼品类 | B9: 12
A10: 其他物资 | B10: 2
A11: 通用物资 | B11: 12
A12: 油污整治 | B12: 4
A13: 总计 | B13: 95
